Workbook

Sheet 2025
A1: Year | B1: Opp. No. | C1: Folder No. | D1: Folder Name | E1: SFDC Opportunity title | F1: End User | G1: Latest Comment | H1: E+H Refference No | I1: Value in BHD | J1: Status | K1: Reason for Loss | L1: Quote Date | M1: Order date | N1: Approx Delivery Date | O1: Payment Terms | P1: Owner | Q1: Abie Comments
A2: 2024 | B2: 5 | C2: =B2&"-24" -> 5-24 | D2: BAHRAIN SUGAR REFINERY-AIT | E2: Bahrain Sugar Refinery W.L.L.04/24 | F2: Bahrain Sugar Refinery | G2: Offer Submitted | J2: Closed (lost) | K2: Customer Went With Existing Supplier | O2: 100% Advance | P2: Sundar
A3: 2024 | B3: 9 | C3: =B3&"-24" -> 9-24 | D3: ARLA-FIT (SITE JOB) | E3: ARLA FOOD 09/24 | F3: Arla Foods Bahrain S.P.C | G3: PO Received Offer update with 24/25 | I3: 5645.71 | J3: Closed (Payment Received) | L3: 45775 | M3: 45777 | N3: 8-weeks | O3: 30 day from delivery | P3: Sundar
A4: 2024 | B4: 10 | C4: =B4&"-24" -> 10-24 | D4: TENDER 4622 -10/2024 | E4: water quality analyzer tender 4622 | F4: EWA | G4: Final Stage | H4: 202215797510 | I4: 45408 | J4: In Process | L4: 45691 | N4: 12-weeks | O4: 50 % Advance & 50% Against delivery | P4: Sundar
A5: 2024 | B5: 24 | C5: =B5&"-24" -> 24-24 | D5: GULF MARKET-DPIT -24/2024 | E5: Not created | F5: GULF MARKET | G5: Offer Submitted | I5: 6940 | J5: Closed (lost) | K5: Lost To Other OEM Channel | L5: 45314 | N5: 8-weeks | O5: 100% Advance | P5: Sundar
A6: 2024 | B6: 25 | C6: =B6&"-24" -> 25-24 | D6: SEDRES-KSA (FIT) -25/2024 | E6: Not created | F6: Orbitus/Sedres | G6: Offer Submitted | I6: 2224 | J6: Closed (lost) | K6: Customer Decision-Making Delays | L6: 45314 | N6: 8-weeks | O6: 30 day from delivery | P6: Sundar
A7: 2024 | B7: 27 | C7: =B7&"-24" -> 27-24 | D7: BAPCO-LIT | E7: Bapco LIT | F7: Bapco Refining | G7: PO received Offer update with 34/24 | I7: 4840 | J7: Closed (Payment Received) | L7: 45346 | N7: 8-weeks | O7: 30 days from date of de;ivery. | P7: Sundar
A8: 2024 | B8: 53 | C8: =B8&"-24" -> 53-24 | D8: Muharraq WW | E8: Muharraq WW - 53 / 24 - 2005134310 | F8: Muharraq Wastewater Services Co | G8: Offer Submitted | H8: 202417235169 | I8: 111949.9 | J8: Closed (lost) | K8: Customer's Budget Constraints | L8: 45336 | P8: Ebin
A9: 2024 | B9: 86 | C9: =B9&"-24" -> 86-24 | D9: Asia | E9: Tabreed - 86 / 24 - 2005136973 | F9: tabreed | G9: Offer Submitted | H9: 202417367369 | I9: 1825 | J9: Closed (lost) | K9: Lost To Other OEM Channel | L9: 45364 | N9: 8-weeks | O9: 100% advance | P9: Sundar
A10: 2024 | B10: 107 | C10: =B10&"-24" -> 107-24 | D10: TENDER 4623 | G10: Offer Submitted | H10: 202417864391 | J10: In Process | L10: 45805 | P10: Ebin
A11: 2024 | B11: 125 | C11: =B11&"-24" -> 125-24 | D11: TRANS GLOBAL | E11: Transglobal DO 125 / 24 | F11: transglobal contracting | G11: Offer Submitted | H11: 202417900372 | I11: 928.65 | J11: Closed (lost) | K11: Competitor Offered Better Price | L11: 45434 | P11: Ebin
A12: 2024 | B12: 126 | C12: =B12&"-24" -> 126-24 | D12: Tabreed | E12: Tabreed spare 126 / 24 | F12: tabreed | G12: Follow up In Process | H12: 202417900376 | I12: 27606 | J12: Closed (lost) | K12: Customer Decision-Making Delays | L12: 45425 | P12: Sundar
A13: 2024 | B13: 152 | C13: =B13&"-24" -> 152-24 | D13: Gpic verification | E13: gpic various meters recalibration 152 / 24 | F13: GPIC | G13: Not Quoted due to its not part of in our OEM | H13: 202417620721 | J13: Closed (lost) | K13: Technical Issues | O13: 30 days from date of de;ivery. | P13: Sundar
A14: 2024 | B14: 158 | C14: =B14&"-24" -> 158-24 | D14: Al hoty calibration | E14: BAPCO - ALHOTY - calibration 158 / 24 - 2005141841 | F14: Bapco Refining | G14: Offer Submitted | H14: 202417585877 | I14: 7446.2 | J14: Closed (lost) | K14: Competitor Offered Better Price | L14: 45456 | P14: Ebin
A15: 2024 | B15: 171 | C15: =B15&"-24" -> 171-24 | D15: intercol fm | E15: Intercol FM 172 / 24 - 2005143729 | F15: intercol | G15: Offer Submitted | H15: 202417664857 | I15: 14581.43 | J15: Closed (lost) | K15: Competitor Offered Better Price | L15: 45480 | P15: Ebin
A16: 2024 | B16: 176 | C16: =B16&"-24" -> 176-24 | D16: Battery mag EWA trial | E16: Battery mag trial order 176 / 24 - 2005145177 | F16: Ewa | G16: PQ Approval ongoing | H16: 202417685044 | I16: 39147.86 | J16: Closed (Payment Received) | L16: 45539 | P16: Ebin
A17: 2024 | B17: 177 | C17: =B17&"-24" -> 177-24 | D17: GPIC- LIT | E17: GPIC LT 177 / 24 (/lightning/r/006 | F17: GPIC | G17: Under evaluation | H17: 202417702628 | I17: 41820 | J17: Follow-up / Evaluation | L17: 45582 | N17: 16-Weeks | O17: 30 days from date of de;ivery. | P17: Sundar | Q17: when is the next update on this? Add date in comments
A18: 2024 | B18: 180 | C18: =B18&"-24" -> 180-24 | D18: Metitio MOW | E18: Metito MOW 180 / 24 | F18: Ministry of works | G18: Offer Submitted | H18: 202417705248 | I18: 9020.49 | J18: Closed (lost) | K18: Competitor Offered Better Price | L18: 45497 | P18: Ebin
A19: 2024 | B19: 183 | C19: =B19&"-24" -> 183-24 | D19: Metito MOW part2 of 180 | E19: its related to 180 / 24 | F19: Ministry of works | G19: same as 180 / 24 | J19: Closed (lost) | K19: Competitor Offered Better Price | L19: 45497 | P19: Ebin
A20: 2024 | B20: 184 | C20: =B20&"-24" -> 184-24 | D20: BAPCO-TOC | E20: BAPCO-TOC | F20: Bapco Refining | G20: waiting for Tender | H20: 202417725562 | I20: =49719*2 -> 99438 | J20: Follow-up / Evaluation | L20: 45673 | N20: 25-Weeks | O20: 30 days from date of de;ivery. | P20: Sundar | Q20: add follow up date
A21: 2024 | B21: 185 | C21: =B21&"-24" -> 185-24 | D21: BAPCO UPSTREAM DEWPOINT ANALYZER SPARES | E21: DEW POINT 184A/24 & 184B/24 | F21: Bapco Refining | G21: PO received | H21: 202417730033 | I21: 1816.99 | J21: Closed (Payment Received) | L21: 45607 | M21: 45616 | N21: 8-Weeks | O21: 30 days from date of de;ivery. | P21: Sundar
A22: 2024 | B22: 189 | C22: =B22&"-24" -> 189-24 | D22: GPIC-LIT | E22: Not Created | F22: GPIC | G22: FEED is on going & offer not yet submitted | J22: In Process | O22: 30 days from date of de;ivery. | P22: Sundar | Q22: is feed done?
A23: 2024 | B23: 190 | C23: =B23&"-24" -> 190-24 | D23: ALBA 77 temp ammend | E23: 190/24 ALBA 77/24 amendment - 2005146429 | F23: ALUMINIUM BAHRAIN B.S.C.(C) | G23: Offer Submitted | H23: 202417752811 | I23: 8846.13 | J23: Closed (lost) | K23: Competitor Offered Better Price | L23: 45533 | O23: 45 days from date of de;ivery. | P23: Ebin
A24: 2024 | B24: 191 | C24: =B24&"-24" -> 191-24 | D24: TTSJV-SP | E24: Not Created | F24: TTSJV | G24: Not Quoted | J24: Closed (lost) | K24: Product Not Suitable | O24: 30 days from date of de;ivery. | P24: Sundar
A25: 2024 | B25: 193 | C25: =B25&"-24" -> 193-24 | D25: serviq TT | E25: Serviq SEC temp 193 / 24 (/lightn | F25: SERVIQ INTERNATIONAL TRADING | G25: Offer Submitted | H25: 202417767152 | I25: 1665.08 | J25: Closed (lost) | K25: Competitor Offered Better Price | L25: 45517 | P25: Ebin
A26: 2024 | B26: 195 | C26: =B26&"-24" -> 195-24 | D26: BAPCO-LIT | E26: Not Created | F26: Bapco Refining | G26: Offer Submitted / budget quote | I26: 1455.3 | J26: Follow-up / Evaluation | L26: 45553 | O26: 30 days from date of de;ivery. | P26: Sundar | Q26: what happened after budget
A27: 2024 | B27: 197 | C27: =B27&"-24" -> 197-24 | D27: ALBA AA06451 | E27: Alba - AA06451 197 / 24 - 2005148081 | F27: ALUMINIUM BAHRAIN B.S.C.(C) | G27: Offer Submitted | H27: 202518842182 | I27: 6884.63 | J27: Closed (lost) | K27: Competitor Offered Better Price | L27: 45522 | O27: 45 days from date of de;ivery. | P27: Ebin
A28: 2024 | B28: 200 | C28: =B28&"-24" -> 200-24 | D28: GPIC-LIT | E28: GPIC | F28: GPIC | G28: PO received | H28: Quotation 2005148555 | I28: 92536 | J28: Closed (Payment Received) | L28: 45694 | M28: 45706 | N28: 16-Weeks | O28: 30 days from date of de;ivery. | P28: Sundar
A29: 2024 | B29: 201 | C29: =B29&"-24" -> 201-24 | D29: BANAGAS-SP | E29: BANAGAS | F29: BANAGAS | G29: PO received | H29: 202417864513 | I29: 14995 | J29: Closed (Payment Received) | L29: 45671 | M29: 45690 | N29: 8-weeks | O29: 30 days from date of de;ivery. | P29: Sundar
A30: 2024 | B30: 202 | C30: =B30&"-24" -> 202-24 | D30: YOKOGAWA-FIT | E30: Not Created | F30: YOKOGAWA | G30: Offer Submitted | I30: 6375 | J30: Closed (lost) | K30: Competitor Offered Better Price | L30: 45556 | N30: 10-Weeks | O30: 30 days from date of de;ivery. | P30: Sundar
A31: 2024 | B31: 203 | C31: =B31&"-24" -> 203-24 | D31: Asia Y6740 | E31: ASIA Y6740 203 / 24 | F31: ASIABAH Accelerated Services | G31: Offer Submitted | H31: 202417912088 | I31: 1099.85 | J31: Closed (lost) | K31: Competitor Offered Better Price | L31: 45528 | P31: Ebin
A32: 2024 | B32: 204 | C32: =B32&"-24" -> 204-24 | D32: ALBA AA04072 | E32: ALBA AA04072 204 / 24-2005148079 | F32: ALUMINIUM BAHRAIN B.S.C.(C) | G32: Offer Submitted | H32: 202417800034 | I32: 10374.38 | J32: Closed (lost) | K32: Competitor Offered Better Price | L32: 45529 | O32: 45 days from date of de;ivery. | P32: Ebin
A33: 2024 | B33: 207 | C33: =B33&"-24" -> 207-24 | D33: Asia y6732 | E33: ASIA Y6732 207 / 24 - 2005149515 | F33: ASIABAH Accelerated Services | G33: Offer Submitted | H33: 202417850350 | I33: 9012.19 | J33: Closed (lost) | K33: Competitor Offered Better Price | L33: 45895 | P33: Ebin
A34: 2024 | B34: 209 | C34: =B34&"-24" -> 209-24 | D34: Muharraq TE | E34: Muharraq WW Incinerator TE 209 /24 - 2005148229 | F34: Muharraq Wastewater Services Co | G34: Offer Submitted | H34: 202417805321 | I34: 5130.14 | J34: Closed (lost) | K34: Competitor Offered Better Price | L34: 45551 | P34: Ebin
A35: 2024 | B35: 211 | C35: =B35&"-24" -> 211-24 | D35: Wabag chlorine | E35: Wabag Chlorine sensor 211 /24-2005148303 | F35: Wabag Belhasa JV WLL | G35: Offer Submitted | H35: 202417807939 | I35: 3540.41 | J35: Closed (lost) | K35: Competitor Offered Better Price | L35: 45901 | O35: 30 days from date of delivery. | P35: Ebin
A36: 2024 | B36: 212 | C36: =B36&"-24" -> 212-24 | D36: Muharraq FM | E36: Muharraq WW FM 212 / 24-2005148296 | F36: Muharraq Wastewater Services Co | G36: Offer Submitted | H36: 202417807879 | I36: 1404.7 | J36: Closed (lost) | K36: Competitor Offered Better Price | L36: 45900 | P36: Ebin
A37: 2024 | B37: 213 | C37: =B37&"-24" -> 213-24 | D37: Asia y6722 | E37: Asia Y6722 PT 213 / 24-2005148304 | F37: ASIABAH Accelerated Services | G37: Offer Submitted | H37: 202417807986 | I37: 777.9 | J37: Closed (lost) | K37: Competitor Offered Better Price | L37: 45896 | P37: Ebin
A38: 2024 | B38: 214 | C38: =B38&"-24" -> 214-24 | D38: Nomac chemicals | E38: Nomac reagents 214 / 24-2005148437 | F38: NOMAC | G38: Offer Submitted | H38: 202417812362 | I38: 301.66 | J38: Closed (Payment Received) | L38: 45585 | O38: 30 days from date of de;ivery. | P38: Ebin
A39: 2024 | B39: 215 | C39: =B39&"-24" -> 215-24 | D39: intercol clampon | E39: Intercol clmpon 215 / 24-2005148636 | F39: intercol | G39: Offer Submitted | H39: 202417819523 | I39: 5734 | J39: Closed (lost) | K39: Customer's Budget Constraints | L39: 31-Sep-2024 | N39: 10-weeks | O39: 30 days from date of de;ivery. | P39: Sundar
A40: 2024 | B40: 217 | C40: =B40&"-24" -> 217-24 | D40: veolia pt | E40: Veolia PT 217 / 24-2005148659 | F40: Veolia Energy Gulf W.L.L. | G40: Offer Submitted | H40: 202417819756 | I40: 787.39 | J40: Closed (Payment Received) | L40: 45536 | M40: 45581 | N40: 45646 | O40: 30 days from date of de;ivery. | P40: Ebin
...

Sheet E+H
A1: Sr. No. | B1: File No | C1: Project | D1: Customer | E1: Offer Date | F1: E+H Invoice | G1: PH Trading Invoice | H1: Invoice date | I1: Invoice | J1: VAT | K1: Total Sale with VAT | L1: Cost | M1: VAT | N1: Cost with VAT | O1: Status | P1: Completion Month
A2: 1 | B2: 10 | C2: 151-23 | D2: Nomac | E2: 45182 | F2: 6017348293 | G2: PH24/004 | H2: 45315 | I2: 950.5 | J2: 95.05 | K2: =IFERROR(IF(I2=0,"",(I2*0.1)+I2),"") -> 1045.55 | L2: 860.528 | M2: =IFERROR(IF(L2=0,"",L2*0.1),"") -> 86.0528 | N2: =IFERROR(IF(L2=0,"",(L2*0.1)+L2),"") -> 946.5808 | O2: =IF(G2="","Pending Update",IF(G2="Yet to Invoice","WIP","Completed")) -> Completed | P2: =IF(H2="","",MONTH(H2)) -> 1
A3: 2 | B3: 10 | C3: 127-23 | D3: Al Ezzel Engie O&M Co. W.L.L | E3: 45182 | F3: 6017353906 | G3: PH24/036 | H3: 45025 | I3: 9800 | J3: 980 | K3: =IFERROR(IF(I3=0,"",(I3*0.1)+I3),"") -> 10780 | L3: 6308.699 | M3: =IFERROR(IF(L3=0,"",L3*0.1),"") -> 630.8699 | N3: =IFERROR(IF(L3=0,"",(L3*0.1)+L3),"") -> 6939.5689 | O3: =IF(G3="","Pending Update",IF(G3="Yet to Invoice","WIP","Completed")) -> Completed | P3: =IF(H3="","",MONTH(H3)) -> 4
A4: 3 | B4: 10 | C4: 172-23 | D4: Al Ezzel Engie O&M Co. W.L.L | E4: 45209 | F4: 6017348297 | G4: PH24/003 | H4: 45312 | I4: 2190 | J4: 219 | K4: =IFERROR(IF(I4=0,"",(I4*0.1)+I4),"") -> 2409 | L4: 2031.924 | M4: =IFERROR(IF(L4=0,"",L4*0.1),"") -> 203.1924 | N4: =IFERROR(IF(L4=0,"",(L4*0.1)+L4),"") -> 2235.1164 | O4: =IF(G4="","Pending Update",IF(G4="Yet to Invoice","WIP","Completed")) -> Completed | P4: =IF(H4="","",MONTH(H4)) -> 1
A5: 4 | B5: 10 | C5: 147-23 | D5: ALUMINIUM BAHRAIN B.S.C.(C) | E5: 45169 | F5: 6017350763 | G5: PH24/021 | H5: 45337 | I5: 650 | J5: 65 | K5: =IFERROR(IF(I5=0,"",(I5*0.1)+I5),"") -> 715 | L5: 649.88 | M5: =IFERROR(IF(L5=0,"",L5*0.1),"") -> 64.988 | N5: =IFERROR(IF(L5=0,"",(L5*0.1)+L5),"") -> 714.868 | O5: =IF(G5="","Pending Update",IF(G5="Yet to Invoice","WIP","Completed")) -> Completed | P5: =IF(H5="","",MONTH(H5)) -> 2
A6: 5 | B6: 10 | C6: 163-23 | D6: TTSJV | E6: 45220 | F6: 6017350803 | G6: PH24/024 | H6: 45348 | I6: 9618 | J6: 961.8 | K6: =IFERROR(IF(I6=0,"",(I6*0.1)+I6),"") -> 10579.8 | L6: 7947.326 | M6: =IFERROR(IF(L6=0,"",L6*0.1),"") -> 794.7326 | N6: =IFERROR(IF(L6=0,"",(L6*0.1)+L6),"") -> 8742.0586 | O6: =IF(G6="","Pending Update",IF(G6="Yet to Invoice","WIP","Completed")) -> Completed | P6: =IF(H6="","",MONTH(H6)) -> 2
A7: 6 | B7: 10 | C7: 160-23 | D7: TTSJV | E7: 45204 | F7: 6017349724 | G7: PH24/027 | H7: 45372 | I7: 16170 | J7: 1617 | K7: =IFERROR(IF(I7=0,"",(I7*0.1)+I7),"") -> 17787 | M7: =IFERROR(IF(L7=0,"",L7*0.1),"") | N7: =IFERROR(IF(L7=0,"",(L7*0.1)+L7),"") | O7: =IF(G7="","Pending Update",IF(G7="Yet to Invoice","WIP","Completed")) -> Completed | P7: =IF(H7="","",MONTH(H7)) -> 3
A8: 7 | B8: 10 | C8: 160-23 | D8: TTSJV | E8: 45204 | F8: Check comments | G8: PH24/073 | H8: 45454 | I8: 1870 | J8: 187 | K8: =IFERROR(IF(I8=0,"",(I8*0.1)+I8),"") -> 2057 | M8: =IFERROR(IF(L8=0,"",L8*0.1),"") | N8: =IFERROR(IF(L8=0,"",(L8*0.1)+L8),"") | O8: =IF(G8="","Pending Update",IF(G8="Yet to Invoice","WIP","Completed")) -> Completed | P8: =IF(H8="","",MONTH(H8)) -> 6
A9: 8 | B9: 10 | C9: 186-23 | D9: Bahrain LNG/ Seapeak | E9: 45225 | F9: 6017348294 | G9: PH24/005 | H9: 45315 | I9: 1048 | J9: 104.8 | K9: =IFERROR(IF(I9=0,"",(I9*0.1)+I9),"") -> 1152.8 | L9: 874.362 | M9: =IFERROR(IF(L9=0,"",L9*0.1),"") -> 87.4362 | N9: =IFERROR(IF(L9=0,"",(L9*0.1)+L9),"") -> 961.7982 | O9: =IF(G9="","Pending Update",IF(G9="Yet to Invoice","WIP","Completed")) -> Completed | P9: =IF(H9="","",MONTH(H9)) -> 1
A10: 9 | B10: 10 | C10: 193-23 | D10: Wabag Belhasa JV WLL | E10: 45229 | F10: Check comments | G10: PH24/032 | H10: 45384 | I10: 4135.71 | J10: 413.571 | K10: =IFERROR(IF(I10=0,"",(I10*0.1)+I10),"") -> 4549.281 | L10: 2672.55 | M10: =IFERROR(IF(L10=0,"",L10*0.1),"") -> 267.255 | N10: =IFERROR(IF(L10=0,"",(L10*0.1)+L10),"") -> 2939.805 | O10: =IF(G10="","Pending Update",IF(G10="Yet to Invoice","WIP","Completed")) -> Completed | P10: =IF(H10="","",MONTH(H10)) -> 4
A11: 10 | B11: 10 | C11: 229-23 | D11: Muharraq Wastewater Services Co | E11: 45266 | F11: 6037463204 | G11: PH24/073 | H11: 45305 | I11: 725 | J11: 72.5 | K11: =IFERROR(IF(I11=0,"",(I11*0.1)+I11),"") -> 797.5 | L11: 502.116 | M11: =IFERROR(IF(L11=0,"",L11*0.1),"") -> 50.2116 | N11: =IFERROR(IF(L11=0,"",(L11*0.1)+L11),"") -> 552.3276 | O11: =IF(G11="","Pending Update",IF(G11="Yet to Invoice","WIP","Completed")) -> Completed | P11: =IF(H11="","",MONTH(H11)) -> 1
A12: 11 | B12: 10 | C12: 194-23 | D12: Delta Bahrain | E12: 45190 | F12: 6037463204 | G12: PH24/001 | H12: 45305 | I12: 450 | J12: 45 | K12: =IFERROR(IF(I12=0,"",(I12*0.1)+I12),"") -> 495 | L12: 359.252 | M12: =IFERROR(IF(L12=0,"",L12*0.1),"") -> 35.9252 | N12: =IFERROR(IF(L12=0,"",(L12*0.1)+L12),"") -> 395.1772 | O12: =IF(G12="","Pending Update",IF(G12="Yet to Invoice","WIP","Completed")) -> Completed | P12: =IF(H12="","",MONTH(H12)) -> 1
A13: 12 | B13: 10 | C13: 233-23 | D13: Tabreed | E13: 45271 | F13: 6037463206 | G13: PH24/018 | H13: 45336 | I13: 7500 | J13: 750 | K13: =IFERROR(IF(I13=0,"",(I13*0.1)+I13),"") -> 8250 | L13: 7006.399 | M13: =IFERROR(IF(L13=0,"",L13*0.1),"") -> 700.6399 | N13: =IFERROR(IF(L13=0,"",(L13*0.1)+L13),"") -> 7707.0389 | O13: =IF(G13="","Pending Update",IF(G13="Yet to Invoice","WIP","Completed")) -> Completed | P13: =IF(H13="","",MONTH(H13)) -> 2
A14: 13 | B14: 10 | C14: 228-23 | D14: TTSJV | E14: 45264 | F14: 6017349716 | G14: PH24/007 | H14: 45322 | I14: 276 | J14: 27.6 | K14: =IFERROR(IF(I14=0,"",(I14*0.1)+I14),"") -> 303.6 | L14: 229.475 | M14: =IFERROR(IF(L14=0,"",L14*0.1),"") -> 22.9475 | N14: =IFERROR(IF(L14=0,"",(L14*0.1)+L14),"") -> 252.4225 | O14: =IF(G14="","Pending Update",IF(G14="Yet to Invoice","WIP","Completed")) -> Completed | P14: =IF(H14="","",MONTH(H14)) -> 1
A15: 14 | B15: 10 | C15: 230-23 | D15: TTSJV | E15: 45270 | F15: 6017349731 | G15: PH24/008 | H15: 45322 | I15: 1450 | J15: 145 | K15: =IFERROR(IF(I15=0,"",(I15*0.1)+I15),"") -> 1595 | L15: 1182.976 | M15: =IFERROR(IF(L15=0,"",L15*0.1),"") -> 118.2976 | N15: =IFERROR(IF(L15=0,"",(L15*0.1)+L15),"") -> 1301.2736 | O15: =IF(G15="","Pending Update",IF(G15="Yet to Invoice","WIP","Completed")) -> Completed | P15: =IF(H15="","",MONTH(H15)) -> 1
A16: 15 | B16: 10 | C16: 181-23 | D16: Bahrain Sugar Refinery | E16: 45234 | F16: 6017349718 | G16: PH24/010 | H16: 45322 | I16: 3077 | J16: 307.7 | K16: =IFERROR(IF(I16=0,"",(I16*0.1)+I16),"") -> 3384.7 | L16: 2626.505 | M16: =IFERROR(IF(L16=0,"",L16*0.1),"") -> 262.6505 | N16: =IFERROR(IF(L16=0,"",(L16*0.1)+L16),"") -> 2889.1555 | O16: =IF(G16="","Pending Update",IF(G16="Yet to Invoice","WIP","Completed")) -> Completed | P16: =IF(H16="","",MONTH(H16)) -> 1
A17: 16 | B17: 10 | C17: 215-23 | D17: Asia | E17: 45250 | F17: 6017349719 | G17: PH24/011 | H17: 45322 | I17: 310 | J17: 31 | K17: =IFERROR(IF(I17=0,"",(I17*0.1)+I17),"") -> 341 | L17: 290.369 | M17: =IFERROR(IF(L17=0,"",L17*0.1),"") -> 29.0369 | N17: =IFERROR(IF(L17=0,"",(L17*0.1)+L17),"") -> 319.4059 | O17: =IF(G17="","Pending Update",IF(G17="Yet to Invoice","WIP","Completed")) -> Completed | P17: =IF(H17="","",MONTH(H17)) -> 1
A18: 17 | B18: 10 | C18: 244-23 | D18: HARSCO | E18: 45286 | F18: 6017349720 | G18: PH24/012 | H18: 45322 | I18: 250 | J18: 25 | K18: =IFERROR(IF(I18=0,"",(I18*0.1)+I18),"") -> 275 | L18: 213.93 | M18: =IFERROR(IF(L18=0,"",L18*0.1),"") -> 21.393 | N18: =IFERROR(IF(L18=0,"",(L18*0.1)+L18),"") -> 235.323 | O18: =IF(G18="","Pending Update",IF(G18="Yet to Invoice","WIP","Completed")) -> Completed | P18: =IF(H18="","",MONTH(H18)) -> 1
A19: 18 | B19: 10 | C19: 242-23 | D19: Gulf Snipe Services W.L.L | E19: 45285 | F19: 6017349721 | G19: PH24/009 | H19: 45322 | I19: 218 | J19: 21.8 | K19: =IFERROR(IF(I19=0,"",(I19*0.1)+I19),"") -> 239.8 | L19: 176.649 | M19: =IFERROR(IF(L19=0,"",L19*0.1),"") -> 17.6649 | N19: =IFERROR(IF(L19=0,"",(L19*0.1)+L19),"") -> 194.3139 | O19: =IF(G19="","Pending Update",IF(G19="Yet to Invoice","WIP","Completed")) -> Completed | P19: =IF(H19="","",MONTH(H19)) -> 1
A20: 19 | B20: 10 | C20: 212-23 | D20: Nomac | E20: 45178 | F20: 6017349722 | G20: PH24/013 | H20: 45322 | I20: 544 | J20: 54.4 | K20: =IFERROR(IF(I20=0,"",(I20*0.1)+I20),"") -> 598.4 | L20: 522.325 | M20: =IFERROR(IF(L20=0,"",L20*0.1),"") -> 52.2325 | N20: =IFERROR(IF(L20=0,"",(L20*0.1)+L20),"") -> 574.5575 | O20: =IF(G20="","Pending Update",IF(G20="Yet to Invoice","WIP","Completed")) -> Completed | P20: =IF(H20="","",MONTH(H20)) -> 1
A21: 20 | B21: 10 | C21: 238-23 | D21: Veolia | E21: 45287 | F21: 6017350766 | G21: PH24/022 | H21: 45337 | I21: 610 | J21: 61 | K21: =IFERROR(IF(I21=0,"",(I21*0.1)+I21),"") -> 671 | L21: 388.62 | M21: =IFERROR(IF(L21=0,"",L21*0.1),"") -> 38.862 | N21: =IFERROR(IF(L21=0,"",(L21*0.1)+L21),"") -> 427.482 | O21: =IF(G21="","Pending Update",IF(G21="Yet to Invoice","WIP","Completed")) -> Completed | P21: =IF(H21="","",MONTH(H21)) -> 2
A22: 21 | B22: 10 | C22: 200-23 | D22: Gpic | E22: 45301 | F22: 6017350767 | G22: PH24/20 | H22: 45338 | I22: 599.9 | J22: 59.99 | K22: =IFERROR(IF(I22=0,"",(I22*0.1)+I22),"") -> 659.89 | L22: 564.851 | M22: =IFERROR(IF(L22=0,"",L22*0.1),"") -> 56.4851 | N22: =IFERROR(IF(L22=0,"",(L22*0.1)+L22),"") -> 621.3361 | O22: =IF(G22="","Pending Update",IF(G22="Yet to Invoice","WIP","Completed")) -> Completed | P22: =IF(H22="","",MONTH(H22)) -> 2
... A37: 36 | B37: 12 | C37: 47-24 | D37: Delta Bahrain | E37: 45327 | F37: 6017355672 | G37: PH24/016 | H37: 45335 | I37: 250 | J37: 25 | K37: =IFERROR(IF(I37=0,"",(I37*0.1)+I37),"") -> 275 | L37: 229.068 | M37: =IFERROR(IF(L37=0,"",L37*0.1),"") -> 22.9068 | N37: =IFERROR(IF(L37=0,"",(L37*0.1)+L37),"") -> 251.9748 | O37: =IF(G37="","Pending Update",IF(G37="Yet to Invoice","WIP","Completed")) -> Completed | P37: =IF(H37="","",MONTH(H37)) -> 2
A38: 37 | B38: 12 | C38: 170-23 | D38: BAPCO UPSTREAM W.L.L | E38: 45248 | F38: Check comments | G38: PH24/060 | H38: 45414 | I38: 6114 | J38: 611.4 | K38: =IFERROR(IF(I38=0,"",(I38*0.1)+I38),"") -> 6725.4 | L38: 5283.992 | M38: =IFERROR(IF(L38=0,"",L38*0.1),"") -> 528.3992 | N38: =IFERROR(IF(L38=0,"",(L38*0.1)+L38),"") -> 5812.3912 | O38: =IF(G38="","Pending Update",IF(G38="Yet to Invoice","WIP","Completed")) -> Completed | P38: =IF(H38="","",MONTH(H38)) -> 5
A39: 38 | B39: 12 | C39: 55-23 | D39: BAPCO UPSTREAM W.L.L | E39: 45005 | F39: 6017353456 | G39: PH24/050 | H39: 45390 | I39: 1173 | J39: 117.3 | K39: =IFERROR(IF(I39=0,"",(I39*0.1)+I39),"") -> 1290.3 | L39: 943.031 | M39: =IFERROR(IF(L39=0,"",L39*0.1),"") -> 94.3031 | N39: =IFERROR(IF(L39=0,"",(L39*0.1)+L39),"") -> 1037.3341 | O39: =IF(G39="","Pending Update",IF(G39="Yet to Invoice","WIP","Completed")) -> Completed | P39: =IF(H39="","",MONTH(H39)) -> 4
A40: 39 | B40: 12 | C40: 66-24 | D40: Veolia | E40: 45343 | F40: 6017353908 | G40: PH24/038 | H40: 45388 | I40: 1097.25 | J40: 109.725 | K40: =IFERROR(IF(I40=0,"",(I40*0.1)+I40),"") -> 1206.975 | L40: 983.506 | M40: =IFERROR(IF(L40=0,"",L40*0.1),"") -> 98.3506 | N40: =IFERROR(IF(L40=0,"",(L40*0.1)+L40),"") -> 1081.8566 | O40: =IF(G40="","Pending Update",IF(G40="Yet to Invoice","WIP","Completed")) -> Completed | P40: =IF(H40="","",MONTH(H40)) -> 4
A41: 40 | B41: 12 | C41: 46-24 | D41: TTSJV | E41: 45335 | F41: 6017355535 | G41: PH24/057 | H41: 45411 | I41: 10950 | J41: 1095 | K41: =IFERROR(IF(I41=0,"",(I41*0.1)+I41),"") -> 12045 | L41: 8470.137 | M41: =IFERROR(IF(L41=0,"",L41*0.1),"") -> 847.0137 | N41: =IFERROR(IF(L41=0,"",(L41*0.1)+L41),"") -> 9317.1507 | O41: =IF(G41="","Pending Update",IF(G41="Yet to Invoice","WIP","Completed")) -> Completed | P41: =IF(H41="","",MONTH(H41)) -> 4
A42: 41 | B42: 12 | C42: 33-24 | D42: TTSJV | E42: 45312 | F42: 6017353457 | G42: PH24/043 | H42: 45391 | I42: 192 | J42: 19.2 | K42: =IFERROR(IF(I42=0,"",(I42*0.1)+I42),"") -> 211.2 | L42: 142.107 | M42: =IFERROR(IF(L42=0,"",L42*0.1),"") -> 14.2107 | N42: =IFERROR(IF(L42=0,"",(L42*0.1)+L42),"") -> 156.3177 | O42: =IF(G42="","Pending Update",IF(G42="Yet to Invoice","WIP","Completed")) -> Completed | P42: =IF(H42="","",MONTH(H42)) -> 4
A43: 42 | B43: 12 | C43: 65-24 | D43: Muharraq Wastewater Services Co | E43: 45342 | F43: 6017353458 | G43: PH24/044 | H43: 45391 | I43: 690 | J43: 69 | K43: =IFERROR(IF(I43=0,"",(I43*0.1)+I43),"") -> 759 | L43: 627.385 | M43: =IFERROR(IF(L43=0,"",L43*0.1),"") -> 62.7385 | N43: =IFERROR(IF(L43=0,"",(L43*0.1)+L43),"") -> 690.1235 | O43: =IF(G43="","Pending Update",IF(G43="Yet to Invoice","WIP","Completed")) -> Completed | P43: =IF(H43="","",MONTH(H43)) -> 4
A44: 43 | B44: 12 | C44: 19-24 | D44: Muharraq Wastewater Services Co | E44: 45328 | F44: 6017353459 | G44: PH24/045 | H44: 45391 | I44: 3500 | J44: 350 | K44: =IFERROR(IF(I44=0,"",(I44*0.1)+I44),"") -> 3850 | L44: 2947.194 | M44: =IFERROR(IF(L44=0,"",L44*0.1),"") -> 294.7194 | N44: =IFERROR(IF(L44=0,"",(L44*0.1)+L44),"") -> 3241.9134 | O44: =IF(G44="","Pending Update",IF(G44="Yet to Invoice","WIP","Completed")) -> Completed | P44: =IF(H44="","",MONTH(H44)) -> 4
A45: 44 | B45: 12 | C45: 23-24 | D45: ALUMINIUM BAHRAIN B.S.C.(C) | E45: 45348 | F45: 6017353460 | G45: PH24/046 | H45: 45391 | I45: 5426 | J45: 542.6 | K45: =IFERROR(IF(I45=0,"",(I45*0.1)+I45),"") -> 5968.6 | L45: 4873.94 | M45: =IFERROR(IF(L45=0,"",L45*0.1),"") -> 487.394 | N45: =IFERROR(IF(L45=0,"",(L45*0.1)+L45),"") -> 5361.334 | O45: =IF(G45="","Pending Update",IF(G45="Yet to Invoice","WIP","Completed")) -> Completed | P45: =IF(H45="","",MONTH(H45)) -> 4
A46: 45 | B46: 12 | C46: 64-24 | D46: Sulb | E46: 45350 | F46: 6017353461 | G46: PH24/047 | H46: 45391 | I46: 558 | J46: 55.8 | K46: =IFERROR(IF(I46=0,"",(I46*0.1)+I46),"") -> 613.8 | L46: 492.772 | M46: =IFERROR(IF(L46=0,"",L46*0.1),"") -> 49.2772 | N46: =IFERROR(IF(L46=0,"",(L46*0.1)+L46),"") -> 542.0492 | O46: =IF(G46="","Pending Update",IF(G46="Yet to Invoice","WIP","Completed")) -> Completed | P46: =IF(H46="","",MONTH(H46)) -> 4
A47: 46 | B47: 12 | C47: 34-24 | D47: BAPCO UPSTREAM W.L.L | E47: 45346 | F47: 6017353909 | G47: PH24/049 | H47: 45398 | I47: 4840 | J47: 484 | K47: =IFERROR(IF(I47=0,"",(I47*0.1)+I47),"") -> 5324 | L47: 3854.099 | M47: =IFERROR(IF(L47=0,"",L47*0.1),"") -> 385.4099 | N47: =IFERROR(IF(L47=0,"",(L47*0.1)+L47),"") -> 4239.5089 | O47: =IF(G47="","Pending Update",IF(G47="Yet to Invoice","WIP","Completed")) -> Completed | P47: =IF(H47="","",MONTH(H47)) -> 4
A48: 47 | B48: 12 | C48: 216-23 | D48: TTSJV | E48: 45349 | F48: 3009395803 | G48: PH24/114 | H48: 45575 | I48: 22000.675 | J48: 2200.0675 | K48: =IFERROR(IF(I48=0,"",(I48*0.1)+I48),"") -> 24200.742 | L48: 18530.543 | M48: =IFERROR(IF(L48=0,"",L48*0.1),"") -> 1853.0543 | N48: =IFERROR(IF(L48=0,"",(L48*0.1)+L48),"") -> 20383.598 | O48: =IF(G48="","Pending Update",IF(G48="Yet to Invoice","WIP","Completed")) -> Completed | P48: =IF(H48="","",MONTH(H48)) -> 10
A49: 48 | B49: 12 | C49: 62-24 | D49: Arla Foods Bahrain S.P.C | E49: 45340 | F49: 6017353462 | G49: PH02/048 | H49: 45391 | I49: 1540 | J49: 154 | K49: =IFERROR(IF(I49=0,"",(I49*0.1)+I49),"") -> 1694 | L49: 1223.136 | M49: =IFERROR(IF(L49=0,"",L49*0.1),"") -> 122.3136 | N49: =IFERROR(IF(L49=0,"",(L49*0.1)+L49),"") -> 1345.4496 | O49: =IF(G49="","Pending Update",IF(G49="Yet to Invoice","WIP","Completed")) -> Completed | P49: =IF(H49="","",MONTH(H49)) -> 4
A50: 49 | B50: 12 | C50: 57-24 | D50: BAPCO UPSTREAM W.L.L | E50: 45346 | F50: 6017355536 | G50: PH24/061 | H50: 45418 | I50: 2860 | J50: 286 | K50: =IFERROR(IF(I50=0,"",(I50*0.1)+I50),"") -> 3146 | L50: 2440.641 | M50: =IFERROR(IF(L50=0,"",L50*0.1),"") -> 244.0641 | N50: =IFERROR(IF(L50=0,"",(L50*0.1)+L50),"") -> 2684.7051 | O50: =IF(G50="","Pending Update",IF(G50="Yet to Invoice","WIP","Completed")) -> Completed | P50: =IF(H50="","",MONTH(H50)) -> 5
... A55: 54 | B55: 13 | C55: 77-23 | D55: Comsip | E55: 45266 | F55: 6017353452 | G55: PH24/035 | H55: 45386 | I55: 14700 | J55: 1470 | K55: =IFERROR(IF(I55=0,"",(I55*0.1)+I55),"") -> 16170 | L55: 11673.834 | M55: =IFERROR(IF(L55=0,"",L55*0.1),"") -> 1167.3834 | N55: =IFERROR(IF(L55=0,"",(L55*0.1)+L55),"") -> 12841.217 | O55: =IF(G55="","Pending Update",IF(G55="Yet to Invoice","WIP","Completed")) -> Completed | P55: =IF(H55="","",MONTH(H55)) -> 4
A56: 55 | B56: 13 | C56: 10-24-other | D56: GPIC | E56: 44977 | F56: 9340 alhillo | G56: PH24/034 | H56: 45391 | I56: 300.25 | J56: 30.025 | K56: =IFERROR(IF(I56=0,"",(I56*0.1)+I56),"") -> 330.275 | L56: 345 | M56: =IFERROR(IF(L56=0,"",L56*0.1),"") -> 34.5 | N56: =IFERROR(IF(L56=0,"",(L56*0.1)+L56),"") -> 379.5 | O56: =IF(G56="","Pending Update",IF(G56="Yet to Invoice","WIP","Completed")) -> Completed | P56: =IF(H56="","",MONTH(H56)) -> 4
A57: 56 | B57: 13 | C57: 21-24 | D57: Al Ezzel Engie O&M Co. W.L.L | E57: 44738 | F57: 6017359660 | G57: PH24/076 | H57: 45475 | I57: 3960 | J57: 396 | K57: =IFERROR(IF(I57=0,"",(I57*0.1)+I57),"") -> 4356 | L57: 3054.028 | M57: =IFERROR(IF(L57=0,"",L57*0.1),"") -> 305.4028 | N57: =IFERROR(IF(L57=0,"",(L57*0.1)+L57),"") -> 3359.4308 | O57: =IF(G57="","Pending Update",IF(G57="Yet to Invoice","WIP","Completed")) -> Completed | P57: =IF(H57="","",MONTH(H57)) -> 7
A58: 57 | B58: 13 | C58: 139-23 | D58: Airmech | E58: 45349 | F58: 6017359661 | G58: PH24/075 | H58: 45475 | I58: 15178.35 | J58: 1517.835 | K58: =IFERROR(IF(I58=0,"",(I58*0.1)+I58),"") -> 16696.185 | L58: 12766.071 | M58: =IFERROR(IF(L58=0,"",L58*0.1),"") -> 1276.6071 | N58: =IFERROR(IF(L58=0,"",(L58*0.1)+L58),"") -> 14042.678 | O58: =IF(G58="","Pending Update",IF(G58="Yet to Invoice","WIP","Completed")) -> Completed | P58: =IF(H58="","",MONTH(H58)) -> 7
...

Sheet GIC
A1: Sr. No. | B1: File No | C1: Project | D1: Customer | E1: Offer Date | F1: GIC Invoice | G1: PH Trading Invoice | H1: Invoice | I1: VAT | J1: Total Sale with VAT | K1: Cost | L1: VAT | M1: Cost with VAT | N1: Profit | O1: VAT | P1: Total Profit | Q1: Profit % | R1: working on file
A2: 1 | B2: 13 | C2: 01-24 GI | D2: Yokogawa | E2: 45285 | F2: PF -331 GBIPL /23-24 | G2: PH24/059 | H2: 196.221 | I2: =IFERROR(IF(H2=0,"",H2*0.1),"") -> 19.6221 | J2: =IFERROR(IF(H2=0,"",(H2*0.1)+H2),"") -> 215.8431 | K2: 173.068 | L2: =IF(K2=0,"",K2*0.1) -> 17.3068 | M2: =IF(K2=0,"",(K2*0.1)+K2) -> 190.3748 | N2: =IF(K2=0,"",H2-K2) -> 23.153 | O2: =IFERROR(IF(N2=0,"",N2*0.1),"") -> 2.3153 | P2: =IFERROR(IF(K2=0,"",N2*0.1)+N2,"") -> 25.4683 | Q2: =IFERROR(IF(K2=0,"",H2-K2)/K2,"") -> 0.13377979 | R2: Completed
A3: 2 | B3: 3 | C3: 03-24GI | D3: Veolia | E3: 45514 | F3: PF-199 GBIPL/24-25 | G3: PH24/153 | H3: 1752 | I3: =IFERROR(IF(H3=0,"",H3*0.1),"") -> 175.2 | J3: =IFERROR(IF(H3=0,"",(H3*0.1)+H3),"") -> 1927.2 | K3: 1371.459 | L3: =IF(K3=0,"",K3*0.1) -> 137.1459 | M3: =IF(K3=0,"",(K3*0.1)+K3) -> 1508.6049 | N3: =IF(K3=0,"",H3-K3) -> 380.541 | O3: =IFERROR(IF(N3=0,"",N3*0.1),"") -> 38.0541 | P3: =IFERROR(IF(K3=0,"",N3*0.1)+N3,"") -> 418.5951 | Q3: =IFERROR(IF(K3=0,"",H3-K3)/K3,"") -> 0.27747166 | R3: Completed
A4: 3 | B4: 9 | C4: 09-24GI | D4: Seapeak | E4: 45502 | F4: PF 173 GBIPL/24-25 | G4: PH24/123 | H4: 300.004 | I4: =IFERROR(IF(H4=0,"",H4*0.1),"") -> 30.0004 | J4: =IFERROR(IF(H4=0,"",(H4*0.1)+H4),"") -> 330.0044 | K4: 245.163 | L4: =IF(K4=0,"",K4*0.1) -> 24.5163 | M4: =IF(K4=0,"",(K4*0.1)+K4) -> 269.6793 | N4: =IF(K4=0,"",H4-K4) -> 54.841 | O4: =IFERROR(IF(N4=0,"",N4*0.1),"") -> 5.4841 | P4: =IFERROR(IF(K4=0,"",N4*0.1)+N4,"") -> 60.3251 | Q4: =IFERROR(IF(K4=0,"",H4-K4)/K4,"") -> 0.22369199 | R4: Completed
A5: 4 | B5: 10 | C5: 10-24GI | D5: Seapeak | E5: 45504 | F5: PF-168 GBIPL/24-25 | G5: PH24/105 | H5: 1110 | I5: =IFERROR(IF(H5=0,"",H5*0.1),"") -> 111 | J5: =IFERROR(IF(H5=0,"",(H5*0.1)+H5),"") -> 1221 | K5: 839.608 | L5: =IF(K5=0,"",K5*0.1) -> 83.9608 | M5: =IF(K5=0,"",(K5*0.1)+K5) -> 923.5688 | N5: =IF(K5=0,"",H5-K5) -> 270.392 | O5: =IFERROR(IF(N5=0,"",N5*0.1),"") -> 27.0392 | P5: =IFERROR(IF(K5=0,"",N5*0.1)+N5,"") -> 297.4312 | Q5: =IFERROR(IF(K5=0,"",H5-K5)/K5,"") -> 0.32204553 | R5: Completed
A6: 5 | B6: 8 | C6: 08-24GI | D6: Panorama | E6: 45483 | G6: PH24/132 | H6: 223 | I6: =IFERROR(IF(H6=0,"",H6*0.1),"") -> 22.3 | J6: =IFERROR(IF(H6=0,"",(H6*0.1)+H6),"") -> 245.3 | K6: 188.246 | L6: =IF(K6=0,"",K6*0.1) -> 18.8246 | M6: =IF(K6=0,"",(K6*0.1)+K6) -> 207.0706 | N6: =IF(K6=0,"",H6-K6) -> 34.754 | O6: =IFERROR(IF(N6=0,"",N6*0.1),"") -> 3.4754 | P6: =IFERROR(IF(K6=0,"",N6*0.1)+N6,"") -> 38.2294 | Q6: =IFERROR(IF(K6=0,"",H6-K6)/K6,"") -> 0.18462012 | R6: Completed
A7: 6 | B7: 11 | C7: 11-24 GI | D7: BANAGAS | E7: 45578 | F7: PF - 356 GBIPL/24-25 | G7: PH25-004 | H7: 3927.5 | I7: =IFERROR(IF(H7=0,"",H7*0.1),"") -> 392.75 | J7: =IFERROR(IF(H7=0,"",(H7*0.1)+H7),"") -> 4320.25 | K7: 3109.86 | L7: =IF(K7=0,"",K7*0.1) -> 310.986 | M7: =IF(K7=0,"",(K7*0.1)+K7) -> 3420.846 | N7: =IF(K7=0,"",H7-K7) -> 817.64 | O7: =IFERROR(IF(N7=0,"",N7*0.1),"") -> 81.764 | P7: =IFERROR(IF(K7=0,"",N7*0.1)+N7,"") -> 899.404 | Q7: =IFERROR(IF(K7=0,"",H7-K7)/K7,"") -> 0.26291859 | R7: Completed
A8: 7 | B8: 19 | C8: 19 - 24 GI | D8: BANAGAS | E8: 45631 | F8: PF - 400 GBIPL/24-25 | H8: 440 | I8: =IFERROR(IF(H8=0,"",H8*0.1),"") -> 44 | J8: =IFERROR(IF(H8=0,"",(H8*0.1)+H8),"") -> 484 | K8: 367.041 | L8: =IF(K8=0,"",K8*0.1) -> 36.7041 | M8: =IF(K8=0,"",(K8*0.1)+K8) -> 403.7451 | N8: =IF(K8=0,"",H8-K8) -> 72.959 | O8: =IFERROR(IF(N8=0,"",N8*0.1),"") -> 7.2959 | P8: =IFERROR(IF(K8=0,"",N8*0.1)+N8,"") -> 80.2549 | Q8: =IFERROR(IF(K8=0,"",H8-K8)/K8,"") -> 0.19877616 | R8: Completed
A9: 8 | B9: 5 | C9: 05 - 25 GI | D9: TATWEER | E9: 45725 | H9: 2940 | I9: =IFERROR(IF(H9=0,"",H9*0.1),"") -> 294 | J9: 3234 | K9: 1814.877 | L9: =IF(K9=0,"",K9*0.1) -> 181.4877 | M9: =IF(K9=0,"",(K9*0.1)+K9) -> 1996.3647 | N9: =IF(K9=0,"",H9-K9) -> 1125.123 | O9: =IFERROR(IF(N9=0,"",N9*0.1),"") -> 112.5123 | P9: =IFERROR(IF(K9=0,"",N9*0.1)+N9,"") -> 1237.6353 | Q9: =IFERROR(IF(K9=0,"",H9-K9)/K9,"") -> 0.61994449 | R9: in production
M13: =M2+M3+M4+M5+M6+M7+M8+M9 -> 8920.2542 | P13: =(P2+P3+P4+P5+P6+P7+P8+P9) -> 3057.3433

Sheet Other brands
A1: File No | B1: Project | C1: Customer | D1: Offer Date | E1: Invoice | F1: PH Trading Invoice | G1: Invoice | H1: VAT | I1: Total Sale with VAT | J1: Cost | K1: VAT | L1: Cost with VAT | M1: Profit | N1: VAT | O1: Total Profit | P1: Profit % | Q1: working on file
A2: 13 | B2: 05-24 other | C2: Veolia | D2: 45363 | G2: 432.48 | H2: =IFERROR(IF(G2=0,"",G2*0.1),"") -> 43.248 | I2: =IFERROR(IF(G2=0,"",(G2*0.1)+G2),"") -> 475.728 | J2: 408 | K2: =IF(J2=0,"",J2*0.1) -> 40.8 | L2: =IF(J2=0,"",(J2*0.1)+J2) -> 448.8 | M2: =IF(J2=0,"",G2-J2) -> 24.48 | N2: =IFERROR(IF(M2=0,"",M2*0.1),"") -> 2.448 | O2: =IFERROR(IF(J2=0,"",M2*0.1)+M2,"") -> 26.928 | P2: =IFERROR(IF(J2=0,"",G2-J2)/J2,"") -> 0.06
A3: 12 | B3: 8-24 | C3: veolia water technologies | D3: 45321 | E3: Alhillo 9237 | F3: PH 24-015 | G3: 306 | H3: =IFERROR(IF(G3=0,"",G3*0.1),"") -> 30.6 | I3: =IFERROR(IF(G3=0,"",(G3*0.1)+G3),"") -> 336.6 | J3: 291.45 | K3: =IF(J3=0,"",J3*0.1) -> 29.145 | L3: =IF(J3=0,"",(J3*0.1)+J3) -> 320.595 | M3: =IF(J3=0,"",G3-J3) -> 14.55 | N3: =IFERROR(IF(M3=0,"",M3*0.1),"") -> 1.455 | O3: =IFERROR(IF(J3=0,"",M3*0.1)+M3,"") -> 16.005 | P3: =IFERROR(IF(J3=0,"",G3-J3)/J3,"") -> 0.0499228
A4: 12 | B4: 4-24 | C4: Veolia-suez | D4: 45386 | E4: Ningbo Qingyang Automation Technology Co,.LT | F4: PH 24-051 | G4: 1568.34 | H4: =IFERROR(IF(G4=0,"",G4*0.1),"") -> 156.834 | I4: =IFERROR(IF(G4=0,"",(G4*0.1)+G4),"") -> 1725.174 | J4: 1264.548 | K4: =IF(J4=0,"",J4*0.1) -> 126.4548 | L4: =IF(J4=0,"",(J4*0.1)+J4) -> 1391.0028 | M4: =IF(J4=0,"",G4-J4) -> 303.792 | N4: =IFERROR(IF(M4=0,"",M4*0.1),"") -> 30.3792 | O4: =IFERROR(IF(J4=0,"",M4*0.1)+M4,"") -> 334.1712 | P4: =IFERROR(IF(J4=0,"",G4-J4)/J4,"") -> 0.24023762
A5: 13 | B5: 10-24' | C5: GPIC | D5: 45285 | E5: Alhillo 9340 | F5: PH 24-034 | G5: 300.258 | H5: =IFERROR(IF(G5=0,"",G5*0.1),"") -> 30.0258 | I5: =G5+H5 -> 330.2838 | J5: 396.762 | K5: =IF(J5=0,"",J5*0.1) -> 39.6762 | L5: 330.275 | M5: =IF(J5=0,"",G5-J5) -> -96.504 | N5: =IFERROR(IF(M5=0,"",M5*0.1),"") -> -9.6504 | O5: =IFERROR(IF(J5=0,"",M5*0.1)+M5,"") -> -106.1544 | P5: =IFERROR(IF(J5=0,"",G5-J5)/J5,"") -> -0.24322894 | R5: costing sheet missing
A6: 13 | B6: T23-24 | C6: Bapco Upstream | D6: 45371 | E6: PrudentN5460-IN-P3510-0424 | G6: 19638 | H6: =IFERROR(IF(G6=0,"",G6*0.1),"") -> 1963.8 | I6: =IFERROR(IF(G6=0,"",(G6*0.1)+G6),"") -> 21601.8 | J6: 18005.852 | K6: =IF(J6=0,"",J6*0.1) -> 1800.5852 | L6: =IF(J6=0,"",(J6*0.1)+J6) -> 19806.437 | M6: =IF(J6=0,"",G6-J6) -> 1632.148 | N6: =IFERROR(IF(M6=0,"",M6*0.1),"") -> 163.2148 | O6: =IFERROR(IF(J6=0,"",M6*0.1)+M6,"") -> 1795.3628 | P6: =IFERROR(IF(J6=0,"",G6-J6)/J6,"") -> 0.090645419
B7: 20-24' | C7: sulb | E7: Servomex | G7: 25719.279 | H7: =IFERROR(IF(G7=0,"",G7*0.1),"") -> 2571.9279 | I7: =IFERROR(IF(G7=0,"",(G7*0.1)+G7),"") -> 28291.207 | J7: 24465.098 | K7: =IF(J7=0,"",J7*0.1) -> 2446.5098 | L7: =IF(J7=0,"",(J7*0.1)+J7) -> 26911.608 | M7: =IF(J7=0,"",G7-J7) -> 1254.181 | N7: =IFERROR(IF(M7=0,"",M7*0.1),"") -> 125.4181 | O7: =IFERROR(IF(J7=0,"",M7*0.1)+M7,"") -> 1379.5991 | P7: =IFERROR(IF(J7=0,"",G7-J7)/J7,"") -> 0.051264091
B8: 03- 25 ' | C8: Engie | E8: MAS

Sheet Summary
A1: Customer Name | B1: Client Type | C1: Total Opportunities | D1: Successful | E1: Unsuccessful | F1: WIP | G1: Total Sales | H1: Owner | I1: Sale Via | K1: YTD Sales Summary | R1: Customer Summary | X1: Status | Y1: Reasons for Loss | AA1: End user
A2: Ahmedi industries | B2: End Customer | C2: =COUNTIF('2025'!F:F,Summary!A2) -> 0 | D2: =COUNTIFS('2025'!F:F,Summary!A2,'2025'!J:J,$X$6) -> 0 | E2: =COUNTIFS('2025'!F:F,Summary!A2,'2025'!J:J,$X$7) -> 0 | F2: =COUNTIFS('2025'!F:F,Summary!A2,'2025'!J:J,"<>$X$7",'2025'!J:J,"<>$X$6") -> 0 | G2: =SUMIFS('2025'!I:I,'2025'!F:F,Summary!A:A,'2025'!I:I,X6) -> 0 | H2: Ramya | I2: AHS | K2: Name | L2: Customers | M2: Total Opportunities | N2: Complete | O2: Closed Lost | P2: WIP | R2: End Customer | S2: =COUNTIF(B:B,R2) -> 34 | T2: PH | U2: AHS | X2: RFQ Received | Y2: Successfully Closed | AA2: Contractor
A3: Al Ezzel Engie O&M Co. W.L.L | B3: End Customer | C3: =COUNTIF('2025'!F:F,Summary!A3) -> 26 | D3: =COUNTIFS('2025'!F:F,Summary!A3,'2025'!J:J,$X$6) -> 0 | E3: =COUNTIFS('2025'!F:F,Summary!A3,'2025'!J:J,$X$7) -> 0 | F3: =COUNTIFS('2025'!F:F,Summary!A3,'2025'!J:J,"<>X7",'2025'!J:J,"<>X6") -> 26 | G3: =SUMIFS('2025'!I:I,'2025'!F:F,Summary!A:A,'2025'!I:I,X7) -> 0 | H3: Ramya | I3: PH | K3: Sundar | L3: =COUNTIF(H:H,K3) -> 9 | M3: =COUNTIFS('2025'!$P:$P,Summary!$K3,'2025'!J:J,"<>X6",'2025'!J:J,"<>X7") -> 90 | N3: =SUMIFS(D:D,H:H,K3) -> 0 | O3: =COUNTIFS('2025'!$P:$P,Summary!$K3,'2025'!$I:$I,X7) -> 0 | P3: =SUMIFS(F:F,H:H,K3) -> 70 | R3: Engineering Company, EPC/Licensor | S3: =COUNTIF(B:B,R3) -> 12 | U3: AHS | X3: Offer Sent | Y3: Price Too High | AA3: Integrator
A4: ALUMINIUM BAHRAIN B.S.C.(C) | B4: End Customer | C4: =COUNTIF('2025'!F:F,Summary!A4) -> 49 | D4: =COUNTIFS('2025'!F:F,Summary!A4,'2025'!J:J,$X$6) -> 0 | E4: =COUNTIFS('2025'!F:F,Summary!A4,'2025'!J:J,$X$7) -> 0 | F4: =COUNTIFS('2025'!F:F,Summary!A4,'2025'!J:J,"<>X7",'2025'!J:J,"<>X6") -> 49 | G4: =SUMIFS('2025'!I:I,'2025'!F:F,Summary!A:A,'2025'!I:I,X8) -> 0 | H4: Ebin | I4: PH | K4: Ebin | L4: =COUNTIF(H:H,K4) -> 14 | M4: =COUNTIFS('2025'!$P:$P,Summary!$K4,'2025'!J:J,"<>X6",'2025'!J:J,"<>X7") -> 200 | N4: =SUMIFS(D:D,H:H,K4) -> 0 | O4: =COUNTIFS('2025'!$P:$P,Summary!$K4,'2025'!$I:$I,X8) -> 0 | P4: =SUMIFS(F:F,H:H,K4) -> 141 | R4: National Reseller | S4: =COUNTIF(B:B,R4) -> 8 | U4: AHS | X4: Follow-up / Evaluation | Y4: Competitor Offered Better Price | AA4: Trader
A5: Arla Foods Bahrain S.P.C | B5: End Customer | C5: =COUNTIF('2025'!F:F,Summary!A5) -> 12 | D5: =COUNTIFS('2025'!F:F,Summary!A5,'2025'!J:J,$X$6) -> 0 | E5: =COUNTIFS('2025'!F:F,Summary!A5,'2025'!J:J,$X$7) -> 0 | F5: =COUNTIFS('2025'!F:F,Summary!A5,'2025'!J:J,"<>X7",'2025'!J:J,"<>X6") -> 12 | G5: =SUMIFS('2025'!I:I,'2025'!F:F,Summary!A:A,'2025'!I:I,X9) -> 0 | H5: Ramya | I5: PH | K5: Peri | L5: =COUNTIF(H:H,K5) -> 0 | M5: =COUNTIFS('2025'!$P:$P,Summary!$K5,'2025'!J:J,"<>X6",'2025'!J:J,"<>X7") -> 26 | N5: =SUMIFS(D:D,H:H,K5) -> 0 | O5: =COUNTIFS('2025'!$P:$P,Summary!$K5,'2025'!$I:$I,X9) -> 0 | P5: =SUMIFS(F:F,H:H,K5) -> 0 | R5: System Integrator | S5: =COUNTIF(B:B,R5) -> 16 | U5: AHS | X5: PO/LOI Received | Y5: Competitor Offered Better Product
A6: Bahrain LNG/ Seapeak | B6: End Customer | C6: =COUNTIF('2025'!F:F,Summary!A6) -> 11 | D6: =COUNTIFS('2025'!F:F,Summary!A6,'2025'!J:J,$X$6) -> 0 | E6: =COUNTIFS('2025'!F:F,Summary!A6,'2025'!J:J,$X$7) -> 0 | F6: =COUNTIFS('2025'!F:F,Summary!A6,'2025'!J:J,"<>X7",'2025'!J:J,"<>X6") -> 11 | G6: =SUMIFS('2025'!I:I,'2025'!F:F,Summary!A:A,'2025'!I:I,X10) -> 0 | H6: Ebin | I6: PH | K6: Ramya | L6: =COUNTIF(H:H,K6) -> 8 | M6: =COUNTIFS('2025'!$P:$P,Summary!$K6,'2025'!J:J,"<>X6",'2025'!J:J,"<>X7") -> 87 | N6: =SUMIFS(D:D,H:H,K6) -> 0 | O6: =COUNTIFS('2025'!$P:$P,Summary!$K6,'2025'!$I:$I,X10) -> 0 | P6: =SUMIFS(F:F,H:H,K6) -> 45 | R6: Total | S6: =SUM(S2:S5) -> 70 | X6: Order Placed | Y6: Customer's Budget Constraints
A7: Bahrain Steel BSCC (E.C.) - Sulb | B7: End Customer | C7: =COUNTIF('2025'!F:F,Summary!A7) -> 12 | D7: =COUNTIFS('2025'!F:F,Summary!A7,'2025'!J:J,$X$6) -> 0 | E7: =COUNTIFS('2025'!F:F,Summary!A7,'2025'!J:J,$X$7) -> 0 | F7: =COUNTIFS('2025'!F:F,Summary!A7,'2025'!J:J,"<>X7",'2025'!J:J,"<>X6") -> 12 | G7: =SUMIFS('2025'!I:I,'2025'!F:F,Summary!A:A,'2025'!I:I,X11) -> 0 | H7: Ebin | I7: PH | K7: Tenders | L7: 2 | M7: =COUNTIFS('2025'!$P:$P,Summary!$K7,'2025'!J:J,"<>X6",'2025'!J:J,"<>X7") -> 0 | N7: =SUMIFS(D:D,H:H,K7) -> 0 | O7: =COUNTIFS('2025'!$P:$P,Summary!$K7,'2025'!$I:$I,X10) -> 0 | P7: =SUMIFS(F:F,H:H,K7) -> 0 | X7: In Process | Y7: Customer Went With Existing Supplier
A8: Bahrain Sugar Refinery | B8: End Customer | C8: =COUNTIF('2025'!F:F,Summary!A8) -> 9 | D8: =COUNTIFS('2025'!F:F,Summary!A8,'2025'!J:J,$X$6) -> 0 | E8: =COUNTIFS('2025'!F:F,Summary!A8,'2025'!J:J,$X$7) -> 0 | F8: =COUNTIFS('2025'!F:F,Summary!A8,'2025'!J:J,"<>X7",'2025'!J:J,"<>X6") -> 9 | G8: =SUMIFS('2025'!I:I,'2025'!F:F,Summary!A:A,'2025'!I:I,X12) -> 0 | H8: Ebin | I8: PH | K8: Third party | L8: =COUNTIFS(B:B,R3)+COUNTIFS(B:B,R4)+COUNTIFS(B:B,R5) -> 36 | M8: =SUMIFS(C:C,B:B,""<>R2) -> 0 | X8: Delivered | Y8: Product Out of Stock
A9: BANAGAS | B9: End Customer | C9: =COUNTIF('2025'!F:F,Summary!A9) -> 3 | D9: =COUNTIFS('2025'!F:F,Summary!A9,'2025'!J:J,$X$6) -> 0 | E9: =COUNTIFS('2025'!F:F,Summary!A9,'2025'!J:J,$X$7) -> 0 | F9: =COUNTIFS('2025'!F:F,Summary!A9,'2025'!J:J,"<>X7",'2025'!J:J,"<>X6") -> 3 | G9: =SUMIFS('2025'!I:I,'2025'!F:F,Summary!A:A,'2025'!I:I,X13) -> 0 | H9: Sundar | I9: PH | K9: Total | L9: =SUM(L3:L8) -> 69 | M9: =SUM(M3:M5) -> 316 | N9: =SUM(N3:N7) -> 0 | O9: =SUM(O3:O5) -> 0 | P9: =SUM(P3:P5) -> 211 | X9: Closed (Payment Received) | Y9: Delivery Time Too Long
A10: Bapco refining | B10: End Customer | C10: =COUNTIF('2025'!F:F,Summary!A10) -> 16 | D10: =COUNTIFS('2025'!F:F,Summary!A10,'2025'!J:J,$X$6) -> 0 | E10: =COUNTIFS('2025'!F:F,Summary!A10,'2025'!J:J,$X$7) -> 0 | F10: =COUNTIFS('2025'!F:F,Summary!A10,'2025'!J:J,"<>X7",'2025'!J:J,"<>X6") -> 16 | G10: =SUMIFS('2025'!I:I,'2025'!F:F,Summary!A:A,'2025'!I:I,X14) -> 0 | H10: Sundar | I10: PH | X10: Closed (lost) | Y10: Product Not Suitable
A11: BAPCO UPSTREAM W.L.L | B11: End Customer | C11: =COUNTIF('2025'!F:F,Summary!A11) -> 11 | D11: =COUNTIFS('2025'!F:F,Summary!A11,'2025'!J:J,$X$6) -> 0 | E11: =COUNTIFS('2025'!F:F,Summary!A11,'2025'!J:J,$X$7) -> 0 | F11: =COUNTIFS('2025'!F:F,Summary!A11,'2025'!J:J,"<>X7",'2025'!J:J,"<>X6") -> 11 | G11: =SUMIFS('2025'!I:I,'2025'!F:F,Summary!A:A,'2025'!I:I,X15) -> 0 | H11: Sundar | I11: PH | Y11: Insufficient Product Knowledge
A12: Batelco | B12: End Customer | C12: =COUNTIF('2025'!F:F,Summary!A12) -> 0 | D12: =COUNTIFS('2025'!F:F,Summary!A12,'2025'!J:J,$X$6) -> 0 | E12: =COUNTIFS('2025'!F:F,Summary!A12,'2025'!J:J,$X$7) -> 0 | F12: =COUNTIFS('2025'!F:F,Summary!A12,'2025'!J:J,"<>X7",'2025'!J:J,"<>X6") -> 0 | G12: =SUMIFS('2025'!I:I,'2025'!F:F,Summary!A:A,'2025'!I:I,X16) -> 0 | H12: Ramya | I12: PH | Y12: Lack of Customer Trust
A13: CPIC Abahsain Fiberglass WLL | B13: End Customer | C13: =COUNTIF('2025'!F:F,Summary!A13) -> 0 | D13: =COUNTIFS('2025'!F:F,Summary!A13,'2025'!J:J,$X$6) -> 0 | E13: =COUNTIFS('2025'!F:F,Summary!A13,'2025'!J:J,$X$7) -> 0 | F13: =COUNTIFS('2025'!F:F,Summary!A13,'2025'!J:J,"<>X7",'2025'!J:J,"<>X6") -> 0 | G13: =SUMIFS('2025'!I:I,'2025'!F:F,Summary!A:A,'2025'!I:I,X17) -> 0 | H13: Ramya | I13: PH | Y13: Customer's Needs Changed
A14: EWA | B14: End Customer | C14: =COUNTIF('2025'!F:F,Summary!A14) -> 13 | D14: =COUNTIFS('2025'!F:F,Summary!A14,'2025'!J:J,$X$6) -> 0 | E14: =COUNTIFS('2025'!F:F,Summary!A14,'2025'!J:J,$X$7) -> 1 | F14: =COUNTIFS('2025'!F:F,Summary!A14,'2025'!J:J,"<>X7",'2025'!J:J,"<>X6") -> 13 | G14: =SUMIFS('2025'!I:I,'2025'!F:F,Summary!A:A,'2025'!I:I,X18) -> 0 | H14: Sundar | I14: PH | Y14: Poor Customer Service
A15: GARMCO | B15: End Customer | C15: =COUNTIF('2025'!F:F,Summary!A15) -> 3 | D15: =COUNTIFS('2025'!F:F,Summary!A15,'2025'!J:J,$X$6) -> 0 | E15: =COUNTIFS('2025'!F:F,Summary!A15,'2025'!J:J,$X$7) -> 0 | F15: =COUNTIFS('2025'!F:F,Summary!A15,'2025'!J:J,"<>X7",'2025'!J:J,"<>X6") -> 3 | G15: =SUMIFS('2025'!I:I,'2025'!F:F,Summary!A:A,'2025'!I:I,X19) -> 0 | H15: Sundar | I15: PH | Y15: Technical Issues
A16: GPIC | B16: End Customer | C16: =COUNTIF('2025'!F:F,Summary!A16) -> 7 | D16: =COUNTIFS('2025'!F:F,Summary!A16,'2025'!J:J,$X$6) -> 0 | E16: =COUNTIFS('2025'!F:F,Summary!A16,'2025'!J:J,$X$7) -> 1 | F16: =COUNTIFS('2025'!F:F,Summary!A16,'2025'!J:J,"<>X7",'2025'!J:J,"<>X6") -> 7 | G16: =SUMIFS('2025'!I:I,'2025'!F:F,Summary!A:A,'2025'!I:I,X20) -> 0 | H16: Sundar | I16: PH | Y16: Contractual Disputes
A17: Hidd Power Co. BSC | B17: End Customer | C17: =COUNTIF('2025'!F:F,Summary!A17) -> 5 | D17: =COUNTIFS('2025'!F:F,Summary!A17,'2025'!J:J,$X$6) -> 0 | E17: =COUNTIFS('2025'!F:F,Summary!A17,'2025'!J:J,$X$7) -> 0 | F17: =COUNTIFS('2025'!F:F,Summary!A17,'2025'!J:J,"<>X7",'2025'!J:J,"<>X6") -> 5 | G17: =SUMIFS('2025'!I:I,'2025'!F:F,Summary!A:A,'2025'!I:I,X21) -> 0 | H17: Ramya | I17: PH | Y17: Logistical Issues
A18: Ministry of works | B18: End Customer | C18: =COUNTIF('2025'!F:F,Summary!A18) -> 13 | D18: =COUNTIFS('2025'!F:F,Summary!A18,'2025'!J:J,$X$6) -> 0 | E18: =COUNTIFS('2025'!F:F,Summary!A18,'2025'!J:J,$X$7) -> 1 | F18: =COUNTIFS('2025'!F:F,Summary!A18,'2025'!J:J,"<>X7",'2025'!J:J,"<>X6") -> 13 | G18: =SUMIFS('2025'!I:I,'2025'!F:F,Summary!A:A,'2025'!I:I,X22) -> 0 | H18: Sundar | I18: PH | Y18: Incorrect Target Audience
A19: Muharraq Wastewater Services Co | B19: End Customer | C19: =COUNTIF('2025'!F:F,Summary!A19) -> 15 | D19: =COUNTIFS('2025'!F:F,Summary!A19,'2025'!J:J,$X$6) -> 0 | E19: =COUNTIFS('2025'!F:F,Summary!A19,'2025'!J:J,$X$7) -> 0 | F19: =COUNTIFS('2025'!F:F,Summary!A19,'2025'!J:J,"<>X7",'2025'!J:J,"<>X6") -> 15 | G19: =SUMIFS('2025'!I:I,'2025'!F:F,Summary!A:A,'2025'!I:I,X23) -> 0 | H19: Ebin | I19: PH | Y19: Lack of Follow-Up
A20: NOMAC | B20: End Customer | C20: =COUNTIF('2025'!F:F,Summary!A20) -> 4 | D20: =COUNTIFS('2025'!F:F,Summary!A20,'2025'!J:J,$X$6) -> 0 | E20: =COUNTIFS('2025'!F:F,Summary!A20,'2025'!J:J,$X$7) -> 0 | F20: =COUNTIFS('2025'!F:F,Summary!A20,'2025'!J:J,"<>X7",'2025'!J:J,"<>X6") -> 4 | G20: =SUMIFS('2025'!I:I,'2025'!F:F,Summary!A:A,'2025'!I:I,X24) -> 0 | H20: Ebin | I20: PH | Y20: Unfavorable Payment Terms
A21: Saudi Electricity Company | B21: End Customer | C21: =COUNTIF('2025'!F:F,Summary!A21) -> 1 | D21: =COUNTIFS('2025'!F:F,Summary!A21,'2025'!J:J,$X$6) -> 0 | E21: =COUNTIFS('2025'!F:F,Summary!A21,'2025'!J:J,$X$7) -> 0 | F21: =COUNTIFS('2025'!F:F,Summary!A21,'2025'!J:J,"<>X7",'2025'!J:J,"<>X6") -> 1 | G21: =SUMIFS('2025'!I:I,'2025'!F:F,Summary!A:A,'2025'!I:I,X25) -> 0 | H21: Ramya | I21: AHS | Y21: Customer Decision-Making Delays
A22: SEAPEAK | B22: End Customer | C22: =COUNTIF('2025'!F:F,Summary!A22) -> 3 | D22: =COUNTIFS('2025'!F:F,Summary!A22,'2025'!J:J,$X$6) -> 0 | E22: =COUNTIFS('2025'!F:F,Summary!A22,'2025'!J:J,$X$7) -> 0 | F22: =COUNTIFS('2025'!F:F,Summary!A22,'2025'!J:J,"<>X7",'2025'!J:J,"<>X6") -> 3 | G22: =SUMIFS('2025'!I:I,'2025'!F:F,Summary!A:A,'2025'!I:I,X26) -> 0 | H22: Ebin | I22: PH | Y22: Lost To Other OEM Channel
A23: Sepcon | B23: End Customer | C23: =COUNTIF('2025'!F:F,Summary!A23) -> 1 | D23: =COUNTIFS('2025'!F:F,Summary!A23,'2025'!J:J,$X$6) -> 0 | E23: =COUNTIFS('2025'!F:F,Summary!A23,'2025'!J:J,$X$7) -> 0 | F23: =COUNTIFS('2025'!F:F,Summary!A23,'2025'!J:J,"<>X7",'2025'!J:J,"<>X6") -> 1 | G23: =SUMIFS('2025'!I:I,'2025'!F:F,Summary!A:A,'2025'!I:I,X27) -> 0 | H23: Ramya | I23: PH | Q23: Stage | R23: Excel Status | S23: Trigger/Logic | Y23: Legal or Regulatory Issues
A24: tabreed | B24: End Customer | C24: =COUNTIF('2025'!F:F,Summary!A24) -> 7 | D24: =COUNTIFS('2025'!F:F,Summary!A24,'2025'!J:J,$X$6) -> 0 | E24: =COUNTIFS('2025'!F:F,Summary!A24,'2025'!J:J,$X$7) -> 0 | F24: =COUNTIFS('2025'!F:F,Summary!A24,'2025'!J:J,"<>X7",'2025'!J:J,"<>X6") -> 7 | G24: =SUMIFS('2025'!I:I,'2025'!F:F,Summary!A:A,'2025'!I:I,X28) -> 0 | H24: Ebin | I24: PH | P24: RFQ | Q24: 1 | R24: RFQ Received | S24: Any new request for quotation (tender, inbound call, site visit, lead gen).
A25: US NAVAL BASE | B25: End Customer | C25: =COUNTIF('2025'!F:F,Summary!A25) -> 0 | D25: =COUNTIFS('2025'!F:F,Summary!A25,'2025'!J:J,$X$6) -> 0 | E25: =COUNTIFS('2025'!F:F,Summary!A25,'2025'!J:J,$X$7) -> 0 | F25: =COUNTIFS('2025'!F:F,Summary!A25,'2025'!J:J,"<>X7",'2025'!J:J,"<>X6") -> 0 | G25: =SUMIFS('2025'!I:I,'2025'!F:F,Summary!A:A,'2025'!I:I,X29) -> 0 | H25: Sundar | I25: PH | P25: COST,OFFER | Q25: 2 | R25: Offer Sent | S25: when you submit any Commercial/technical proposal with prices, payment terms, etc.
A26: Veolia Energy Gulf W.L.L. | B26: End Customer | C26: =COUNTIF('2025'!F:F,Summary!A26) -> 11 | D26: =COUNTIFS('2025'!F:F,Summary!A26,'2025'!J:J,$X$6) -> 0 | E26: =COUNTIFS('2025'!F:F,Summary!A26,'2025'!J:J,$X$7) -> 1 | F26: =COUNTIFS('2025'!F:F,Summary!A26,'2025'!J:J,"<>X7",'2025'!J:J,"<>X6") -> 11 | G26: =SUMIFS('2025'!I:I,'2025'!F:F,Summary!A:A,'2025'!I:I,X30) -> 0 | H26: Ebin | I26: PH | P26: WORKING,OEM OFFER | Q26: 3 | R26: Follow-up / Evaluation | S26: Customer is reviewing, clarifications ongoing, budget discussions, feed activity.
A27: VEOLIA Water Tech & Solutions | B27: End Customer | C27: =COUNTIF('2025'!F:F,Summary!A27) -> 5 | D27: =COUNTIFS('2025'!F:F,Summary!A27,'2025'!J:J,$X$6) -> 0 | E27: =COUNTIFS('2025'!F:F,Summary!A27,'2025'!J:J,$X$7) -> 0 | F27: =COUNTIFS('2025'!F:F,Summary!A27,'2025'!J:J,"<>X7",'2025'!J:J,"<>X6") -> 5 | G27: =SUMIFS('2025'!I:I,'2025'!F:F,Summary!A:A,'2025'!I:I,X31) -> 0 | H27: Ebin | I27: PH | P27: EXECUTION, PO, LOI , DN , PI,INVOICE | Q27: 4 | R27: PO/LOI Received | S27: Customer issues Purchase Order or Letter of Intent.
A28: Wabag Belhasa JV WLL | B28: End Customer | C28: =COUNTIF('2025'!F:F,Summary!A28) -> 5 | D28: =COUNTIFS('2025'!F:F,Summary!A28,'2025'!J:J,$X$6) -> 0 | E28: =COUNTIFS('2025'!F:F,Summary!A28,'2025'!J:J,$X$7) -> 0 | F28: =COUNTIFS('2025'!F:F,Summary!A28,'2025'!J:J,"<>X7",'2025'!J:J,"<>X6") -> 5 | G28: =SUMIFS('2025'!I:I,'2025'!F:F,Summary!A:A,'2025'!I:I,X32) -> 0 | H28: Ebin | I28: PH | P28: PROJECT ENGINEERING, PROJECT MATERIAL SUBMITTAL | Q28: 5 | R28: Order Placed | S28: when you place Internal order booking, OEM/supplier is engaged.
A29: YOKOGAWA | B29: End Customer | C29: =COUNTIF('2025'!F:F,Summary!A29) -> 4 | D29: =COUNTIFS('2025'!F:F,Summary!A29,'2025'!J:J,$X$6) -> 0 | E29: =COUNTIFS('2025'!F:F,Summary!A29,'2025'!J:J,$X$7) -> 0 | F29: =COUNTIFS('2025'!F:F,Summary!A29,'2025'!J:J,"<>X7",'2025'!J:J,"<>X6") -> 4 | G29: =SUMIFS('2025'!I:I,'2025'!F:F,Summary!A:A,'2025'!I:I,X33) -> 0 | H29: Sundar | I29: AHS | Q29: 6 | R29: In Process | S29: Order under execution: manufacturing, shipping, customs clearance, delivery.
A30: AluServ Middle East W.L.L. | B30: End Customer | C30: =COUNTIF('2025'!F:F,Summary!A30) -> 3 | D30: =COUNTIFS('2025'!F:F,Summary!A30,'2025'!J:J,$X$6) -> 0 | E30: =COUNTIFS('2025'!F:F,Summary!A30,'2025'!J:J,$X$7) -> 0 | F30: =COUNTIFS('2025'!F:F,Summary!A30,'2025'!J:J,"<>X7",'2025'!J:J,"<>X6") -> 3 | G30: =SUMIFS('2025'!I:I,'2025'!F:F,Summary!A:A,'2025'!I:I,X34) -> 0 | H30: Ebin | I30: AHS | Q30: 7 | R30: Delivered | S30: Goods physically delivered to customer site.
A31: Kuwait Oil company | B31: End Customer | C31: =COUNTIF('2025'!F:F,Summary!A31) -> 1 | D31: =COUNTIFS('2025'!F:F,Summary!A31,'2025'!J:J,$X$6) -> 0 | E31: =COUNTIFS('2025'!F:F,Summary!A31,'2025'!J:J,$X$7) -> 0 | F31: =COUNTIFS('2025'!F:F,Summary!A31,'2025'!J:J,"<>X7",'2025'!J:J,"<>X6") -> 1 | G31: =SUMIFS('2025'!I:I,'2025'!F:F,Summary!A:A,'2025'!I:I,X35) -> 0 | I31: AHS | Q31: 8 | R31: Closed (Payment Received) | S31: Customer payment credited to bank, opportunity fully completed.
A32: HARSCO | B32: End Customer | C32: =COUNTIF('2025'!F:F,Summary!A32) -> 0 | D32: =COUNTIFS('2025'!F:F,Summary!A32,'2025'!J:J,$X$6) -> 0 | E32: =COUNTIFS('2025'!F:F,Summary!A32,'2025'!J:J,$X$7) -> 0 | F32: =COUNTIFS('2025'!F:F,Summary!A32,'2025'!J:J,"<>X7",'2025'!J:J,"<>X6") -> 0 | G32: =SUMIFS('2025'!I:I,'2025'!F:F,Summary!A:A,'2025'!I:I,X36) -> 0 | H32: Ebin | I32: AHS | Q32: 9 | R32: Closed (lost) | S32: Select reason for loss
A33: Sulb | B33: End Customer | C33: =COUNTIF('2025'!F:F,Summary!A33) -> 7 | D33: =COUNTIFS('2025'!F:F,Summary!A33,'2025'!J:J,$X$6) -> 0 | E33: =COUNTIFS('2025'!F:F,Summary!A33,'2025'!J:J,$X$7) -> 0 | F33: =COUNTIFS('2025'!F:F,Summary!A33,'2025'!J:J,"<>X7",'2025'!J:J,"<>X6") -> 7 | G33: =SUMIFS('2025'!I:I,'2025'!F:F,Summary!A:A,'2025'!I:I,X37) -> 0 | H33: Ebin | I33: PH
A34: Aluserv | B34: End Customer | C34: =COUNTIF('2025'!F:F,Summary!A34) -> 0 | D34: =COUNTIFS('2025'!F:F,Summary!A34,'2025'!J:J,$X$6) -> 0 | E34: =COUNTIFS('2025'!F:F,Summary!A34,'2025'!J:J,$X$7) -> 0 | F34: =COUNTIFS('2025'!F:F,Summary!A34,'2025'!J:J,"<>X7",'2025'!J:J,"<>X6") -> 0 | G34: =SUMIFS('2025'!I:I,'2025'!F:F,Summary!A:A,'2025'!I:I,X38) -> 0 | I34: AHS
A35: AWAL DAIRY | B35: End Customer | C35: =COUNTIF('2025'!F:F,Summary!A35) -> 3 | D35: =COUNTIFS('2025'!F:F,Summary!A35,'2025'!J:J,$X$6) -> 0 | E35: =COUNTIFS('2025'!F:F,Summary!A35,'2025'!J:J,$X$7) -> 0 | F35: =COUNTIFS('2025'!F:F,Summary!A35,'2025'!J:J,"<>X7",'2025'!J:J,"<>X6") -> 3 | G35: =SUMIFS('2025'!I:I,'2025'!F:F,Summary!A:A,'2025'!I:I,X39) -> 0 | I35: AHS
A36: Airmech W.L.L | B36: Engineering Company, EPC/Licensor | C36: =COUNTIF('2025'!F:F,Summary!A36) -> 1 | D36: =COUNTIFS('2025'!F:F,Summary!A36,'2025'!J:J,$X$6) -> 0 | E36: =COUNTIFS('2025'!F:F,Summary!A36,'2025'!J:J,$X$7) -> 0 | F36: =COUNTIFS('2025'!F:F,Summary!A36,'2025'!J:J,"<>X7",'2025'!J:J,"<>X6") -> 1 | G36: =SUMIFS('2025'!I:I,'2025'!F:F,Summary!A:A,'2025'!I:I,X40) -> 0 | I36: AHS
A37: Delta Bahrain | B37: Engineering Company, EPC/Licensor | C37: =COUNTIF('2025'!F:F,Summary!A37) -> 3 | D37: =COUNTIFS('2025'!F:F,Summary!A37,'2025'!J:J,$X$6) -> 0 | E37: =COUNTIFS('2025'!F:F,Summary!A37,'2025'!J:J,$X$7) -> 0 | F37: =COUNTIFS('2025'!F:F,Summary!A37,'2025'!J:J,"<>X7",'2025'!J:J,"<>X6") -> 3 | G37: =SUMIFS('2025'!I:I,'2025'!F:F,Summary!A:A,'2025'!I:I,X41) -> 0 | I37: AHS
A38: Kraum & Spruk Technologies | B38: Engineering Company, EPC/Licensor | C38: =COUNTIF('2025'!F:F,Summary!A38) -> 1 | D38: =COUNTIFS('2025'!F:F,Summary!A38,'2025'!J:J,$X$6) -> 0 | E38: =COUNTIFS('2025'!F:F,Summary!A38,'2025'!J:J,$X$7) -> 0 | F38: =COUNTIFS('2025'!F:F,Summary!A38,'2025'!J:J,"<>X7",'2025'!J:J,"<>X6") -> 1 | G38: =SUMIFS('2025'!I:I,'2025'!F:F,Summary!A:A,'2025'!I:I,X42) -> 0 | I38: AHS
A39: MCSC | B39: Engineering Company, EPC/Licensor | C39: =COUNTIF('2025'!F:F,Summary!A39) -> 1 | D39: =COUNTIFS('2025'!F:F,Summary!A39,'2025'!J:J,$X$6) -> 0 | E39: =COUNTIFS('2025'!F:F,Summary!A39,'2025'!J:J,$X$7) -> 0 | F39: =COUNTIFS('2025'!F:F,Summary!A39,'2025'!J:J,"<>X7",'2025'!J:J,"<>X6") -> 1 | G39: =SUMIFS('2025'!I:I,'2025'!F:F,Summary!A:A,'2025'!I:I,X43) -> 0 | I39: AHS
A40: Panorama | B40: Engineering Company, EPC/Licensor | C40: =COUNTIF('2025'!F:F,Summary!A40) -> 0 | D40: =COUNTIFS('2025'!F:F,Summary!A40,'2025'!J:J,$X$6) -> 0 | E40: =COUNTIFS('2025'!F:F,Summary!A40,'2025'!J:J,$X$7) -> 0 | F40: =COUNTIFS('2025'!F:F,Summary!A40,'2025'!J:J,"<>X7",'2025'!J:J,"<>X6") -> 0 | G40: =SUMIFS('2025'!I:I,'2025'!F:F,Summary!A:A,'2025'!I:I,X44) -> 0 | I40: AHS
...
